<?xml version="1.0" ?>
<!-- =================================================================================== -->
<!-- |    This document was autogenerated by xacro from turtlebot3_burger.urdf.xacro   | -->
<!-- |    EDITING THIS FILE BY HAND IS NOT RECOMMENDED                                 | -->
<!-- =================================================================================== -->
<robot name="turtlebot3_burger" xmlns:xacro="http://ros.org/wiki/xacro">
  <link name="base_footprint"/>
  <joint name="base_joint" type="fixed">
    <parent link="base_footprint"/>
    <child link="base_link"/>
    <origin rpy="0 0 0" xyz="0.0 0.0 0.100"/>
    <!-- Scaled origin -->
  </joint>
  <link name="base_link">
    <visual>
      <origin rpy="0 0 0" xyz="-0.32 0 0.0"/>
      <!-- Scaled origin -->
      <geometry>
        <mesh filename="C:/Users/Wali/Desktop/RL/burger_base.stl" scale="0.01 0.01 0.01"/>
      </geometry>
      <material name="base_color1">
        <color rgba="0.8 0.1 0.1 1.0"/>
      </material>
    </visual>
    <collision>
      <origin rpy="0 0 0" xyz="-0.32 0 0.700"/>
      <!-- Scaled origin -->
      <geometry>
        <box size="1.400 1.400 1.430"/>
        <!-- Scaled box -->
      </geometry>
    </collision>
    <inertial>
      <origin rpy="0 0 0" xyz="0 0 0"/>
      <mass value="8.2573504"/>
      <!-- Adjusted mass for 10x scale -->
      <inertia ixx="2.2124416e-01" ixy="-1.2294101e-04" ixz="3.4938785e-04" iyy="2.1193702e-01" iyz="-5.0120904e-05" izz="2.0064271e-01"/>
      <!-- Scaled inertia -->
    </inertial>
  </link>
  <joint name="wheel_left_joint" type="continuous">
    <parent link="base_link"/>
    <child link="wheel_left_link"/>
    <origin rpy="-1.57 0 0" xyz="0.0 0.80 0.230"/>
    <!-- Scaled origin -->
    <axis xyz="0 0 1"/>
  </joint>
  <link name="wheel_left_link">
    <visual>
      <origin rpy="1.57 0 0" xyz="0 0 0"/>
      <geometry>
        <mesh filename="./left_tire.stl" scale="0.01 0.01 0.01"/>
        <!-- Scaled mesh -->
      </geometry>
      <material name="base_color2">
        <color rgba="0.1 0.1 0.8 1.0"/>
      </material>
    </visual>
    <collision>
      <origin rpy="0 0 0" xyz="0 0 0"/>
      <geometry>
        <cylinder length="0.180" radius="0.330"/>
        <!-- Scaled cylinder -->
      </geometry>
    </collision>
    <inertial>
      <origin xyz="0 0 0"/>
      <mass value="0.2849894"/>
      <!-- Scaled mass -->
      <inertia ixx="1.1175580e-03" ixy="-4.2369783e-10" ixz="-5.9381719e-08" iyy="1.1192413e-03" iyz="-1.4400107e-10" izz="2.0712558e-03"/>
      <!-- Scaled inertia -->
    </inertial>
  </link>
  <joint name="wheel_right_joint" type="continuous">
    <parent link="base_link"/>
    <child link="wheel_right_link"/>
    <origin rpy="-1.57 0 0" xyz="0.0 -0.800 0.230"/>
    <!-- Scaled origin -->
    <axis xyz="0 0 1"/>
  </joint>
  <link name="wheel_right_link">
    <visual>
      <origin rpy="1.57 0 0" xyz="0 0 0"/>
      <geometry>
        <mesh filename="C:/Users/Wali/Desktop/RL/right_tire.stl" scale="0.01 0.01 0.01"/>
        <!-- Scaled mesh -->
      </geometry>
      <material name="base_color3">
        <color rgba="0.1 0.1 0.8 1.0"/>
      </material>
    </visual>
    <collision>
      <origin rpy="0 0 0" xyz="0 0 0"/>
      <geometry>
        <cylinder length="0.180" radius="0.330"/>
        <!-- Scaled cylinder -->
      </geometry>
    </collision>
    <inertial>
      <origin xyz="0 0 0"/>
      <mass value="0.2849894"/>
      <!-- Scaled mass -->
      <inertia ixx="1.1175580e-03" ixy="-4.2369783e-10" ixz="-5.9381719e-08" iyy="1.1192413e-03" iyz="-1.4400107e-10" izz="2.0712558e-03"/>
      <!-- Scaled inertia -->
    </inertial>
  </link>
  <joint name="caster_back_joint" type="fixed">
    <parent link="base_link"/>
    <child link="caster_back_link"/>
    <origin rpy="-1.57 0 0" xyz="-0.810 0 -0.040"/>
    <!-- Scaled origin -->
  </joint>
  <link name="caster_back_link">
    <collision>
      <origin rpy="0 0 0" xyz="0 0.010 0"/>
      <!-- Scaled origin -->
      <geometry>
        <box size="0.300 0.090 0.200"/>
        <!-- Scaled box -->
      </geometry>
    </collision>
    <inertial>
      <origin xyz="0 0 0"/>
      <mass value="0.050"/>
      <!-- Scaled mass -->
      <inertia ixx="0.010" ixy="0.0" ixz="0.0" iyy="0.010" iyz="0.0" izz="0.010"/>
      <!-- Scaled inertia -->
    </inertial>
  </link>
  <joint name="imu_joint" type="fixed">
    <parent link="base_link"/>
    <child link="imu_link"/>
    <origin rpy="0 0 0" xyz="-0.320 0 0.680"/>
    <!-- Scaled origin -->
  </joint>
  <link name="imu_link"/>
  <joint name="scan_joint" type="fixed">
    <parent link="base_link"/>
    <child link="base_scan"/>
    <origin rpy="0 0 0" xyz="-0.320 0 1.720"/>
    <!-- Scaled origin -->
  </joint>
  <link name="base_scan">
    <visual>
      <origin rpy="0 0 0" xyz="0 0 0.0"/>
      <geometry>
        <mesh filename="package://turtlebot3_description/meshes/sensors/lds.stl" scale="0.01 0.01 0.01"/>
        <!-- Scaled mesh -->
      </geometry>
      <material name="base_color4">
        <color rgba="0.1 0.1 0.8 1.0"/>
      </material>
    </visual>
    <collision>
      <origin rpy="0 0 0" xyz="0.150 0 -0.065"/>
      <!-- Scaled origin -->
      <geometry>
        <cylinder length="0.315" radius="0.550"/>
        <!-- Scaled cylinder -->
      </geometry>
    </collision>
    <inertial>
      <mass value="1.140"/>
      <!-- Scaled mass -->
      <origin xyz="0 0 0"/>
      <inertia ixx="0.010" ixy="0.0" ixz="0.0" iyy="0.010" iyz="0.0" izz="0.010"/>
      <!-- Scaled inertia -->
    </inertial>
  </link>
</robot>

